<sdf version='1.10'>
  <world name='advanced_lift_drag'>
    <plugin name='gz::sim::systems::Physics' filename='gz-sim-physics-system'/>
    <plugin name='gz::sim::systems::UserCommands' filename='gz-sim-user-commands-system'/>
    <plugin name='gz::sim::systems::SceneBroadcaster' filename='gz-sim-scene-broadcaster-system'/>
    <gravity>0 0 -9.8000000000000007</gravity>
    <magnetic_field>5.5644999999999998e-06 2.2875799999999999e-05 -4.2388400000000002e-05</magnetic_field>
    <atmosphere type='adiabatic'/>
    <physics type='ode'>
      <max_step_size>0.001</max_step_size>
      <real_time_factor>1</real_time_factor>
      <real_time_update_rate>1000</real_time_update_rate>
    </physics>
    <scene>
      <ambient>0.400000006 0.400000006 0.400000006 1</ambient>
      <background>0.699999988 0.699999988 0.699999988 1</background>
      <shadows>true</shadows>
    </scene>


    <spherical_coordinates>
      <surface_model>EARTH_WGS84</surface_model>
      <world_frame_orientation>ENU</world_frame_orientation>
      <latitude_deg>37.4</latitude_deg>    <!-- San Francisco Bay Area -->
      <longitude_deg>-122.1</longitude_deg>
      <elevation>5</elevation>
      <heading_deg>0</heading_deg>
    </spherical_coordinates>



    <model name='ground_plane'>
      <static>true</static>
      <link name='link'>
        <collision name='collision'>
          <geometry>
            <plane>
              <normal>0 0 1</normal>
              <size>100 100</size>
            </plane>
          </geometry>
          <surface>
            <friction>
              <ode/>
            </friction>
            <bounce/>
            <contact/>
          </surface>
        </collision>
        <visual name='visual'>
          <geometry>
            <plane>
              <normal>0 0 1</normal>
              <size>100 100</size>
            </plane>
          </geometry>
          <material>
            <ambient>0.800000012 0.800000012 0.800000012 1</ambient>
            <diffuse>0.800000012 0.800000012 0.800000012 1</diffuse>
            <specular>0.800000012 0.800000012 0.800000012 1</specular>
          </material>
        </visual>
        <pose>0 0 0 0 0 0</pose>
        <inertial>
          <pose>0 0 0 0 0 0</pose>
          <mass>1</mass>
          <inertia>
            <ixx>1</ixx>
            <ixy>0</ixy>
            <ixz>0</ixz>
            <iyy>1</iyy>
            <iyz>0</iyz>
            <izz>1</izz>
          </inertia>
        </inertial>
        <enable_wind>false</enable_wind>
      </link>
      <pose>0 0 0 0 0 0</pose>
      <self_collide>false</self_collide>
    </model>
    <model name='advanced_lift_drag_demo_model'>
      <pose>0 0 0.246 0 0 0</pose>
      <link name='base_link'>
        <pose>0 0 0 0 0 0</pose>
        <inertial>
          <pose>0 0 0 0 0 0</pose>
          <mass>1</mass>
          <inertia>
            <ixx>0.19756299999999999</ixx>
            <ixy>0</ixy>
            <ixz>0</ixz>
            <iyy>0.14589289999999999</iyy>
            <iyz>0</iyz>
            <izz>0.1477</izz>
          </inertia>
        </inertial>
        <collision name='base_link_collision'>
          <pose>0 0 -0.070000000000000007 0 0 0</pose>
          <geometry>
            <box>
              <size>0.46999999999999997 0.46999999999999997 0.11</size>
            </box>
          </geometry>
          <surface>
            <contact>
              <ode>
                <max_vel>10</max_vel>
                <min_depth>0.01</min_depth>
              </ode>
            </contact>
            <friction>
              <ode/>
            </friction>
            <bounce/>
          </surface>
        </collision>
        <visual name='base_link_visual'>
          <pose>0.070000000000000007 0 -0.080000000000000002 0 0 0</pose>
          <geometry>
            <mesh>
              <scale>0.10000000000000001 0.10000000000000001 0.10000000000000001</scale>
              <uri>https://fuel.gazebosim.org/1.0/frede791/models/Advanced%20Plane/tip/files/meshes/body.dae</uri>
            </mesh>
          </geometry>
          <material>
            <ambient>0.174999997 0.174999997 0.174999997 1</ambient>
            <diffuse>0.174999997 0.174999997 0.174999997 1</diffuse>
          </material>
        </visual>
        <gravity>true</gravity>
        <velocity_decay/>
        <self_collide>false</self_collide>
        <sensor name='imu_sensor' type='imu'>
          <pose>0 0 0 0 0 0</pose>
          <topic>__default__</topic>
          <update_rate>250</update_rate>
          <enable_metrics>false</enable_metrics>
          <imu>
            <orientation_reference_frame>
              <localization>CUSTOM</localization>
              <custom_rpy>0 0 0</custom_rpy>
              <grav_dir_x>1 0 0</grav_dir_x>
            </orientation_reference_frame>
            <angular_velocity>
              <x>
                <noise type='none'>
                  <mean>0</mean>
                  <stddev>0</stddev>
                  <bias_mean>0</bias_mean>
                  <bias_stddev>0</bias_stddev>
                  <dynamic_bias_stddev>0</dynamic_bias_stddev>
                  <dynamic_bias_correlation_time>0</dynamic_bias_correlation_time>
                  <precision>0</precision>
                </noise>
              </x>
              <y>
                <noise type='none'>
                  <mean>0</mean>
                  <stddev>0</stddev>
                  <bias_mean>0</bias_mean>
                  <bias_stddev>0</bias_stddev>
                  <dynamic_bias_stddev>0</dynamic_bias_stddev>
                  <dynamic_bias_correlation_time>0</dynamic_bias_correlation_time>
                  <precision>0</precision>
                </noise>
              </y>
              <z>
                <noise type='none'>
                  <mean>0</mean>
                  <stddev>0</stddev>
                  <bias_mean>0</bias_mean>
                  <bias_stddev>0</bias_stddev>
                  <dynamic_bias_stddev>0</dynamic_bias_stddev>
                  <dynamic_bias_correlation_time>0</dynamic_bias_correlation_time>
                  <precision>0</precision>
                </noise>
              </z>
            </angular_velocity>
            <linear_acceleration>
              <x>
                <noise type='none'>
                  <mean>0</mean>
                  <stddev>0</stddev>
                  <bias_mean>0</bias_mean>
                  <bias_stddev>0</bias_stddev>
                  <dynamic_bias_stddev>0</dynamic_bias_stddev>
                  <dynamic_bias_correlation_time>0</dynamic_bias_correlation_time>
                  <precision>0</precision>
                </noise>
              </x>
              <y>
                <noise type='none'>
                  <mean>0</mean>
                  <stddev>0</stddev>
                  <bias_mean>0</bias_mean>
                  <bias_stddev>0</bias_stddev>
                  <dynamic_bias_stddev>0</dynamic_bias_stddev>
                  <dynamic_bias_correlation_time>0</dynamic_bias_correlation_time>
                  <precision>0</precision>
                </noise>
              </y>
              <z>
                <noise type='none'>
                  <mean>0</mean>
                  <stddev>0</stddev>
                  <bias_mean>0</bias_mean>
                  <bias_stddev>0</bias_stddev>
                  <dynamic_bias_stddev>0</dynamic_bias_stddev>
                  <dynamic_bias_correlation_time>0</dynamic_bias_correlation_time>
                  <precision>0</precision>
                </noise>
              </z>
            </linear_acceleration>
            <enable_orientation>true</enable_orientation>
          </imu>
        </sensor>
        <sensor name='air_pressure_sensor' type='air_pressure'>
          <pose>0 0 0 0 0 0</pose>
          <topic>__default__</topic>
          <update_rate>50</update_rate>
          <enable_metrics>false</enable_metrics>
          <air_pressure>
            <reference_altitude>0</reference_altitude>
            <pressure>
              <noise type='gaussian'>
                <mean>0</mean>
                <stddev>0.01</stddev>
                <bias_mean>0</bias_mean>
                <bias_stddev>0</bias_stddev>
                <dynamic_bias_stddev>0</dynamic_bias_stddev>
                <dynamic_bias_correlation_time>0</dynamic_bias_correlation_time>
                <precision>0</precision>
              </noise>
            </pressure>
          </air_pressure>
        </sensor>
        <enable_wind>false</enable_wind>
      </link>
      <link name='rotor_puller'>
        <pose>0.29999999999999999 0 0 0 1.5699999999998482 0</pose>
        <inertial>
          <pose>0 0 0 0 0 0</pose>
          <mass>0.0050000000000000001</mass>
          <inertia>
            <ixx>9.7499999999999998e-07</ixx>
            <ixy>0</ixy>
            <ixz>0</ixz>
            <iyy>0.00016670399999999999</iyy>
            <iyz>0</iyz>
            <izz>0.00016760399999999999</izz>
          </inertia>
        </inertial>
        <collision name='rotor_puller_collision'>
          <pose>0 0 0 0 0 0</pose>
          <geometry>
            <cylinder>
              <length>0.0050000000000000001</length>
              <radius>0.10000000000000001</radius>
            </cylinder>
          </geometry>
          <surface>
            <contact>
              <ode/>
            </contact>
            <friction>
              <ode/>
            </friction>
            <bounce/>
          </surface>
        </collision>
        <visual name='rotor_puller_visual'>
          <pose>0 0 -0.089999999999999997 0 0 0</pose>
          <geometry>
            <mesh>
              <scale>1 1 1</scale>
              <uri>https://fuel.gazebosim.org/1.0/frede791/models/Advanced%20Plane/tip/files/meshes/iris_prop_ccw.dae</uri>
            </mesh>
          </geometry>
          <material>
            <ambient>0.174999997 0.174999997 0.174999997 1</ambient>
            <diffuse>0.174999997 0.174999997 0.174999997 1</diffuse>
          </material>
        </visual>
        <gravity>true</gravity>
        <velocity_decay/>
        <self_collide>false</self_collide>
        <enable_wind>false</enable_wind>
      </link>
      <joint name='rotor_puller_joint' type='revolute'>
        <child>rotor_puller</child>
        <parent>base_link</parent>
        <axis>
          <xyz>0.00079632671073326389 0 0.99999968293183472</xyz>
          <limit>
            <lower>-10000000000000000</lower>
            <upper>10000000000000000</upper>
            <effort>inf</effort>
            <velocity>inf</velocity>
            <stiffness>100000000</stiffness>
            <dissipation>1</dissipation>
          </limit>
          <dynamics>
            <spring_reference>0</spring_reference>
            <spring_stiffness>0</spring_stiffness>
            <damping>0</damping>
            <friction>0</friction>
          </dynamics>
        </axis>
        <pose>2.7755575615628914e-17 0 0 0 0 0</pose>
      </joint>
      <link name='left_elevon'>
        <inertial>
          <mass>1e-08</mass>
          <inertia>
            <ixx>9.9999999999999995e-07</ixx>
            <ixy>0</ixy>
            <iyy>9.9999999999999995e-07</iyy>
            <ixz>0</ixz>
            <iyz>0</iyz>
            <izz>9.9999999999999995e-07</izz>
          </inertia>
          <pose>0 0.29999999999999999 0 0 0 0</pose>
        </inertial>
        <visual name='left_elevon_visual'>
          <pose>0.070000000000000007 0 -0.080000000000000002 0 0 0</pose>
          <geometry>
            <mesh>
              <scale>0.10000000000000001 0.10000000000000001 0.10000000000000001</scale>
              <uri>https://fuel.gazebosim.org/1.0/frede791/models/Advanced%20Plane/tip/files/meshes/left_aileron.dae</uri>
            </mesh>
          </geometry>
          <material>
            <ambient>1 0 0 1</ambient>
            <diffuse>1 0 0 1</diffuse>
          </material>
        </visual>
        <pose>0 0 0 0 0 0</pose>
        <enable_wind>false</enable_wind>
      </link>
      <link name='right_elevon'>
        <inertial>
          <mass>1e-08</mass>
          <inertia>
            <ixx>9.9999999999999995e-07</ixx>
            <ixy>0</ixy>
            <iyy>9.9999999999999995e-07</iyy>
            <ixz>0</ixz>
            <iyz>0</iyz>
            <izz>9.9999999999999995e-07</izz>
          </inertia>
          <pose>0 -0.29999999999999999 0 0 0 0</pose>
        </inertial>
        <visual name='right_elevon_visual'>
          <pose>0.070000000000000007 0 -0.080000000000000002 0 0 0</pose>
          <geometry>
            <mesh>
              <scale>0.10000000000000001 0.10000000000000001 0.10000000000000001</scale>
              <uri>https://fuel.gazebosim.org/1.0/frede791/models/Advanced%20Plane/tip/files/meshes/right_aileron.dae</uri>
            </mesh>
          </geometry>
          <material>
            <ambient>1 0 0 1</ambient>
            <diffuse>1 0 0 1</diffuse>
          </material>
        </visual>
        <pose>0 0 0 0 0 0</pose>
        <enable_wind>false</enable_wind>
      </link>
      <link name='left_flap'>
        <inertial>
          <mass>1e-08</mass>
          <inertia>
            <ixx>9.9999999999999995e-07</ixx>
            <ixy>0</ixy>
            <iyy>9.9999999999999995e-07</iyy>
            <ixz>0</ixz>
            <iyz>0</iyz>
            <izz>9.9999999999999995e-07</izz>
          </inertia>
          <pose>0 0.14999999999999999 0 0 0 0</pose>
        </inertial>
        <visual name='left_flap_visual'>
          <pose>0.070000000000000007 0 -0.080000000000000002 0 0 0</pose>
          <geometry>
            <mesh>
              <scale>0.10000000000000001 0.10000000000000001 0.10000000000000001</scale>
              <uri>https://fuel.gazebosim.org/1.0/frede791/models/Advanced%20Plane/tip/files/meshes/left_flap.dae</uri>
            </mesh>
          </geometry>
          <material>
            <ambient>1 0 0 1</ambient>
            <diffuse>1 0 0 1</diffuse>
          </material>
        </visual>
        <pose>0 0 0 0 0 0</pose>
        <enable_wind>false</enable_wind>
      </link>
      <link name='right_flap'>
        <inertial>
          <mass>1e-08</mass>
          <inertia>
            <ixx>9.9999999999999995e-07</ixx>
            <ixy>0</ixy>
            <iyy>9.9999999999999995e-07</iyy>
            <ixz>0</ixz>
            <iyz>0</iyz>
            <izz>9.9999999999999995e-07</izz>
          </inertia>
          <pose>0 -0.14999999999999999 0 0 0 0</pose>
        </inertial>
        <visual name='right_flap_visual'>
          <pose>0.070000000000000007 0 -0.080000000000000002 0 0 0</pose>
          <geometry>
            <mesh>
              <scale>0.10000000000000001 0.10000000000000001 0.10000000000000001</scale>
              <uri>https://fuel.gazebosim.org/1.0/frede791/models/Advanced%20Plane/tip/files/meshes/right_flap.dae</uri>
            </mesh>
          </geometry>
          <material>
            <ambient>1 0 0 1</ambient>
            <diffuse>1 0 0 1</diffuse>
          </material>
        </visual>
        <pose>0 0 0 0 0 0</pose>
        <enable_wind>false</enable_wind>
      </link>
      <link name='elevator'>
        <inertial>
          <mass>1e-08</mass>
          <inertia>
            <ixx>9.9999999999999995e-07</ixx>
            <ixy>0</ixy>
            <iyy>9.9999999999999995e-07</iyy>
            <ixz>0</ixz>
            <iyz>0</iyz>
            <izz>9.9999999999999995e-07</izz>
          </inertia>
          <pose>-0.5 0 0 0 0 0</pose>
        </inertial>
        <visual name='elevator_visual'>
          <pose>0.070000000000000007 0 -0.080000000000000002 0 0 0</pose>
          <geometry>
            <mesh>
              <scale>0.10000000000000001 0.10000000000000001 0.10000000000000001</scale>
              <uri>https://fuel.gazebosim.org/1.0/frede791/models/Advanced%20Plane/tip/files/meshes/elevators.dae</uri>
            </mesh>
          </geometry>
          <material>
            <ambient>1 0 0 1</ambient>
            <diffuse>1 0 0 1</diffuse>
          </material>
        </visual>
        <pose>0 0 0 0 0 0</pose>
        <enable_wind>false</enable_wind>
      </link>
      <link name='rudder'>
        <inertial>
          <mass>1e-08</mass>
          <inertia>
            <ixx>9.9999999999999995e-07</ixx>
            <ixy>0</ixy>
            <iyy>9.9999999999999995e-07</iyy>
            <ixz>0</ixz>
            <iyz>0</iyz>
            <izz>9.9999999999999995e-07</izz>
          </inertia>
          <pose>-0.5 0 0.050000000000000003 0 0 0</pose>
        </inertial>
        <visual name='rudder_visual'>
          <pose>0.070000000000000007 0 -0.080000000000000002 0 0 0</pose>
          <geometry>
            <mesh>
              <scale>0.10000000000000001 0.10000000000000001 0.10000000000000001</scale>
              <uri>https://fuel.gazebosim.org/1.0/frede791/models/Advanced%20Plane/tip/files/meshes/rudder.dae</uri>
            </mesh>
          </geometry>
          <material>
            <ambient>1 0 0 1</ambient>
            <diffuse>1 0 0 1</diffuse>
          </material>
        </visual>
        <pose>0 0 0 0 0 0</pose>
        <enable_wind>false</enable_wind>
      </link>
      <joint name='servo_0' type='revolute'>
        <parent>base_link</parent>
        <child>left_elevon</child>
        <pose>-0.070000000000000007 0.40000000000000002 0.080000000000000002 0 0 0</pose>
        <axis>
          <xyz>0 1 0</xyz>
          <limit>
            <lower>-0.53000000000000003</lower>
            <upper>0.53000000000000003</upper>
            <effort>inf</effort>
            <velocity>inf</velocity>
            <stiffness>100000000</stiffness>
            <dissipation>1</dissipation>
          </limit>
          <dynamics>
            <spring_reference>0</spring_reference>
            <spring_stiffness>0</spring_stiffness>
            <damping>1</damping>
            <friction>0</friction>
          </dynamics>
        </axis>
        <physics>
          <ode>
            <implicit_spring_damper>true</implicit_spring_damper>
          </ode>
        </physics>
      </joint>
      <plugin name='gz::sim::systems::JointPositionController' filename='gz-sim-joint-position-controller-system'>
        <joint_name>servo_0</joint_name>
        <sub_topic>servo_0</sub_topic>
        <p_gain>10</p_gain>
        <i_gain>0</i_gain>
        <d_gain>0</d_gain>
      </plugin>
      <joint name='servo_1' type='revolute'>
        <parent>base_link</parent>
        <child>right_elevon</child>
        <pose>-0.070000000000000007 -0.40000000000000002 0.080000000000000002 0 0 0</pose>
        <axis>
          <xyz>0 1 0</xyz>
          <limit>
            <lower>-0.53000000000000003</lower>
            <upper>0.53000000000000003</upper>
            <effort>inf</effort>
            <velocity>inf</velocity>
            <stiffness>100000000</stiffness>
            <dissipation>1</dissipation>
          </limit>
          <dynamics>
            <spring_reference>0</spring_reference>
            <spring_stiffness>0</spring_stiffness>
            <damping>1</damping>
            <friction>0</friction>
          </dynamics>
        </axis>
        <physics>
          <ode>
            <implicit_spring_damper>true</implicit_spring_damper>
          </ode>
        </physics>
      </joint>
      <plugin name='gz::sim::systems::JointPositionController' filename='gz-sim-joint-position-controller-system'>
        <joint_name>servo_1</joint_name>
        <sub_topic>servo_1</sub_topic>
        <p_gain>10</p_gain>
        <i_gain>0</i_gain>
        <d_gain>0</d_gain>
      </plugin>
      <joint name='servo_4' type='revolute'>
        <parent>base_link</parent>
        <child>left_flap</child>
        <pose>-0.070000000000000007 0.20000000000000001 0.080000000000000002 0 0 0</pose>
        <axis>
          <xyz>0 1 0</xyz>
          <limit>
            <lower>-0.53000000000000003</lower>
            <upper>0.53000000000000003</upper>
            <effort>inf</effort>
            <velocity>inf</velocity>
            <stiffness>100000000</stiffness>
            <dissipation>1</dissipation>
          </limit>
          <dynamics>
            <spring_reference>0</spring_reference>
            <spring_stiffness>0</spring_stiffness>
            <damping>1</damping>
            <friction>0</friction>
          </dynamics>
        </axis>
        <physics>
          <ode>
            <implicit_spring_damper>true</implicit_spring_damper>
          </ode>
        </physics>
      </joint>
      <plugin name='gz::sim::systems::JointPositionController' filename='gz-sim-joint-position-controller-system'>
        <joint_name>servo_4</joint_name>
        <sub_topic>servo_4</sub_topic>
        <p_gain>10</p_gain>
        <i_gain>0</i_gain>
        <d_gain>0</d_gain>
      </plugin>
      <joint name='servo_5' type='revolute'>
        <parent>base_link</parent>
        <child>right_flap</child>
        <pose>-0.070000000000000007 -0.20000000000000001 0.080000000000000002 0 0 0</pose>
        <axis>
          <xyz>0 1 0</xyz>
          <limit>
            <lower>-0.53000000000000003</lower>
            <upper>0.53000000000000003</upper>
            <effort>inf</effort>
            <velocity>inf</velocity>
            <stiffness>100000000</stiffness>
            <dissipation>1</dissipation>
          </limit>
          <dynamics>
            <spring_reference>0</spring_reference>
            <spring_stiffness>0</spring_stiffness>
            <damping>1</damping>
            <friction>0</friction>
          </dynamics>
        </axis>
        <physics>
          <ode>
            <implicit_spring_damper>true</implicit_spring_damper>
          </ode>
        </physics>
      </joint>
      <plugin name='gz::sim::systems::JointPositionController' filename='gz-sim-joint-position-controller-system'>
        <joint_name>servo_5</joint_name>
        <sub_topic>servo_5</sub_topic>
        <p_gain>10</p_gain>
        <i_gain>0</i_gain>
        <d_gain>0</d_gain>
      </plugin>
      <joint name='servo_2' type='revolute'>
        <parent>base_link</parent>
        <child>elevator</child>
        <pose>-0.5 0 0 0 0 0</pose>
        <axis>
          <xyz>0 1 0</xyz>
          <limit>
            <lower>-0.53000000000000003</lower>
            <upper>0.53000000000000003</upper>
            <effort>inf</effort>
            <velocity>inf</velocity>
            <stiffness>100000000</stiffness>
            <dissipation>1</dissipation>
          </limit>
          <dynamics>
            <spring_reference>0</spring_reference>
            <spring_stiffness>0</spring_stiffness>
            <damping>1</damping>
            <friction>0</friction>
          </dynamics>
        </axis>
        <physics>
          <ode>
            <implicit_spring_damper>true</implicit_spring_damper>
          </ode>
        </physics>
      </joint>
      <plugin name='gz::sim::systems::JointPositionController' filename='gz-sim-joint-position-controller-system'>
        <joint_name>servo_2</joint_name>
        <sub_topic>servo_2</sub_topic>
        <p_gain>10</p_gain>
        <i_gain>0</i_gain>
        <d_gain>0</d_gain>
      </plugin>
      <joint name='servo_3' type='revolute'>
        <parent>base_link</parent>
        <child>rudder</child>
        <pose>-0.5 0 0.050000000000000003 0 0 0</pose>
        <axis>
          <xyz>0 0 1</xyz>
          <limit>
            <lower>-0.53000000000000003</lower>
            <upper>0.53000000000000003</upper>
            <effort>inf</effort>
            <velocity>inf</velocity>
            <stiffness>100000000</stiffness>
            <dissipation>1</dissipation>
          </limit>
          <dynamics>
            <spring_reference>0</spring_reference>
            <spring_stiffness>0</spring_stiffness>
            <damping>1</damping>
            <friction>0</friction>
          </dynamics>
        </axis>
        <physics>
          <ode>
            <implicit_spring_damper>true</implicit_spring_damper>
          </ode>
        </physics>
      </joint>
      <plugin name='gz::sim::systems::JointPositionController' filename='gz-sim-joint-position-controller-system'>
        <joint_name>servo_3</joint_name>
        <sub_topic>servo_3</sub_topic>
        <p_gain>10</p_gain>
        <i_gain>0</i_gain>
        <d_gain>0</d_gain>
      </plugin>
      <plugin name='gz::sim::systems::JointStatePublisher' filename='gz-sim-joint-state-publisher-system'/>
      <plugin name='gz::sim::systems::AdvancedLiftDrag' filename='gz-sim-advanced-lift-drag-system'>
        <a0>0.0</a0>
        <CL0>0.15188</CL0>
        <AR>6.5</AR>
        <eff>0.97</eff>
        <CLa>5.015</CLa>
        <CD0>0.029</CD0>
        <Cem0>0.075</Cem0>
        <Cema>-0.463966</Cema>
        <CYb>-0.258244</CYb>
        <Cellb>-0.039250</Cellb>
        <Cenb>0.100826</Cenb>
        <CDp>0.0</CDp>
        <CYp>0.065861</CYp>
        <CLp>0.0</CLp>
        <Cellp>-0.487407</Cellp>
        <Cemp>0.0</Cemp>
        <Cenp>-0.040416</Cenp>
        <CDq>0.055166</CDq>
        <CYq>0.0</CYq>
        <CLq>7.971792</CLq>
        <Cellq>0.0</Cellq>
        <Cemq>-12.140140</Cemq>
        <Cenq>0.0</Cenq>
        <CDr>0.0</CDr>
        <CYr>0.230299</CYr>
        <CLr>0.0</CLr>
        <Cellr>0.078165</Cellr>
        <Cemr>0.0</Cemr>
        <Cenr>-0.089947</Cenr>
        <alpha_stall>0.3391428111</alpha_stall>
        <CLa_stall>-3.85</CLa_stall>
        <CDa_stall>-0.9233984055</CDa_stall>
        <Cema_stall>0</Cema_stall>
        <cp>-0.12 0.0 0.0</cp>
        <area>0.34</area>
        <mac>0.22</mac>
        <air_density>1.2041</air_density>
        <forward>1 0 0</forward>
        <upward>0 0 1</upward>
        <link_name>base_link</link_name>
        <num_ctrl_surfaces>4</num_ctrl_surfaces>
        <control_surface>
          <name>servo_0</name>
          <index>0</index>
          <direction>1</direction>
          <CD_ctrl>-0.000059</CD_ctrl>
          <CY_ctrl>0.000171</CY_ctrl>
          <CL_ctrl>-0.011940</CL_ctrl>
          <Cell_ctrl>-0.003331</Cell_ctrl>
          <Cem_ctrl>0.001498</Cem_ctrl>
          <Cen_ctrl>-0.000057</Cen_ctrl>
        </control_surface>
        <control_surface>
          <name>servo_1</name>
          <direction>1</direction>
          <index>1</index>
          <CD_ctrl>-0.000059</CD_ctrl>
          <CY_ctrl>-0.000171</CY_ctrl>
          <CL_ctrl>-0.011940</CL_ctrl>
          <Cell_ctrl>0.003331</Cell_ctrl>
          <Cem_ctrl>0.001498</Cem_ctrl>
          <Cen_ctrl>0.000057</Cen_ctrl>
        </control_surface>
        <control_surface>
          <name>servo_2</name>
          <direction>-1</direction>
          <index>2</index>
          <CD_ctrl>0.000274</CD_ctrl>
          <CY_ctrl>0</CY_ctrl>
          <CL_ctrl>0.010696</CL_ctrl>
          <Cell_ctrl>0.0</Cell_ctrl>
          <Cem_ctrl>-0.025798</Cem_ctrl>
          <Cen_ctrl>0.0</Cen_ctrl>
        </control_surface>
        <control_surface>
          <name>servo_3</name>b
          <CD_ctrl>0.0</CD_ctrl>
          <CY_ctrl>-0.003913</CY_ctrl>
          <CL_ctrl>0.0</CL_ctrl>
          <Cell_ctrl>-0.000257</Cell_ctrl>
          <Cem_ctrl>0.0</Cem_ctrl>
          <Cen_ctrl>0.001613</Cen_ctrl>
        </control_surface>
      </plugin>
      <plugin name='gz::sim::systems::MulticopterMotorModel' filename='gz-sim-multicopter-motor-model-system'>
        <jointName>rotor_puller_joint</jointName>
        <linkName>rotor_puller</linkName>
        <turningDirection>cw</turningDirection>
        <timeConstantUp>0.0125</timeConstantUp>
        <timeConstantDown>0.025</timeConstantDown>
        <maxRotVelocity>3500</maxRotVelocity>
        <motorConstant>8.54858e-06</motorConstant>
        <momentConstant>0.01</momentConstant>
        <commandSubTopic>command/motor_speed</commandSubTopic>
        <motorNumber>0</motorNumber>
        <rotorDragCoefficient>8.06428e-05</rotorDragCoefficient>
        <rollingMomentCoefficient>1e-06</rollingMomentCoefficient>
        <rotorVelocitySlowdownSim>10</rotorVelocitySlowdownSim>
        <motorType>velocity</motorType>
      </plugin>
      <plugin name='gz::sim::systems::ApplyJointForce' filename='gz-sim-apply-joint-force-system'>
        <joint_name>servo_0</joint_name>
      </plugin>
      <static>false</static>
      <self_collide>false</self_collide>
    </model>
    <light name='sun' type='directional'>
      <pose>0 0 10 0 0 0</pose>
      <cast_shadows>true</cast_shadows>
      <intensity>1</intensity>
      <direction>-0.5 0.10000000000000001 -0.90000000000000002</direction>
      <diffuse>1 1 1 1</diffuse>
      <specular>0.5 0.5 0.5 1</specular>
      <attenuation>
        <range>1000</range>
        <linear>0.01</linear>
        <constant>0.90000000000000002</constant>
        <quadratic>0.001</quadratic>
      </attenuation>
      <spot>
        <inner_angle>0</inner_angle>
        <outer_angle>0</outer_angle>
        <falloff>0</falloff>
      </spot>
    </light>
  </world>
</sdf>
